Workbook

Sheet Raw Data
A1: Customer_ID | B1: Order_ID | C1: Order_Date | D1: Customer_Type | E1: Age_Group | F1: Region | G1: Product_Category | H1: Quantity | I1: Revenue | J1: Cost | K1: Profit | L1: Payment_Method | M1: Customer_Rating
A2: CUST001 | B2: ORD0001 | C2: 46027 | D2: New | E2: 18-25 | F2: East | G2: Electronics | H2: 2 | I2: 8400 | J2: 6300 | K2: 2100 | L2: UPI | M2: 4.2
A3: CUST002 | B3: ORD0002 | C3: 46030 | D3: New | E3: 26-35 | F3: West | G3: Home & Kitchen | H3: 3 | I3: 4500 | J3: 3100 | K3: 1400 | L3: Credit Card | M3: 4.5
A4: CUST003 | B4: ORD0003 | C4: 46034 | D4: Returning | E4: 36-45 | F4: North | G4: North Personal Care | H4: 4 | I4: 3600 | J4: 2400 | K4: 1200 | L4: UPI | M4: 4
A5: CUST004 | B5: ORD0004 | C5: 46040 | D5: New | E5: 26-35 | F5: South | G5: Accessories | H5: 2 | I5: 2800 | J5: 1900 | K5: 900 | L5: Debit Card | M5: 3.8
A6: CUST005 | B6: ORD0005 | C6: 46045 | D6: Returning | E6: 46-55 | F6: East | G6: Electronics | H6: 1 | I6: 6200 | J6: 4700 | K6: 1500 | L6: Credit Card | M6: 4.7
A7: CUST006 | B7: ORD0006 | C7: 46051 | D7: New | E7: 18-25 | F7: West | G7: Personal Care | H7: 5 | I7: 4250 | J7: 2900 | K7: 1350 | L7: UPI | M7: 4.1
A8: CUST007 | B8: ORD0007 | C8: 46056 | D8: Returning | E8: 26-35 | F8: North | G8: Home & Kitchen | H8: 2 | I8: 5200 | J8: 3500 | K8: 1700 | L8: UPI | M8: 4.6
A9: CUST008 | B9: ORD0008 | C9: 46062 | D9: New | E9: 36-45 | F9: South | G9: Electronics | H9: 1 | I9: 4800 | J9: 3600 | K9: 1200 | L9: Debit Card | M9: 3.9
A10: CUST009 | B10: ORD0009 | C10: 46067 | D10: Returning | E10: 26-35 | F10: East | G10: Accessories | H10: 4 | I10: 4400 | J10: 3000 | K10: 1400 | L10: UPI | M10: 4.3
A11: CUST010 | B11: ORD0010 | C11: 46073 | D11: New | E11: 46-55 | F11: West | G11: Home & Kitchen | H11: 3 | I11: 6900 | J11: 4800 | K11: 2100 | L11: Credit Card | M11: 4.8
A12: CUST011 | B12: ORD0011 | C12: 46078 | D12: New | E12: 18-25 | F12: North | G12: Electronics | H12: 2 | I12: 7600 | J12: 5900 | K12: 1700 | L12: UPI | M12: 4
A13: CUST012 | B13: ORD0012 | C13: 46081 | D13: Returning | E13: 36-45 | F13: South | G13: Personal Care | H13: 3 | I13: 2700 | J13: 1750 | K13: 950 | L13: Cash | M13: 3.7
... A51: CUST050 | B51: ORD0050 | C51: 46292 | D51: New | E51: 26-35 | F51: West | G51: Personal Care | H51: 4 | I51: 4600 | J51: 3100 | K51: 1500 | L51: Credit Card | M51: 4.2

Sheet Analysis
A1: Customer & Business Performance Analysis
A3: Total Customers | B3: =COUNTA(CustomerData[Customer_ID]) -> 50
A4: Total Orders | B4: =COUNTA(CustomerData[Order_ID]) -> 50
A5: Total Revenue | B5: =SUM(CustomerData[Revenue]) -> 294600
A6: Total Profit | B6: =SUM(CustomerData[Profit]) -> 84650
A7: Total Quantity | B7: =SUM(CustomerData[Quantity]) -> 146
A8: Profit Margin | B8: =B6/B5 -> 0.28733876
A9: Average Customer Rating | B9: =AVERAGE(CustomerData[Customer_Rating]) -> 4.272
A11: Business Performance Analysis
A12: Revenue by Product Category
A13: Product Category | B13: Revenue
A14: Electronics | B14: =SUMIF(CustomerData[Product_Category],A14,CustomerData[Revenue]) -> 122100
A15: Home & Kitchen | B15: =SUMIF(CustomerData[Product_Category],A15,CustomerData[Revenue]) -> 73700
A16: Personal Care | B16: =SUMIF(CustomerData[Product_Category],A16,CustomerData[Revenue]) -> 39150
A17: Accessories | B17: =SUMIF(CustomerData[Product_Category],A17,CustomerData[Revenue]) -> 48150
A19: Highest Revenue Category | B19: =INDEX(A14:A17,MATCH(MAX(B14:B17),B14:B17,0)) -> Electronics
A21: Revenue by Region
A22: Region | B22: Revenue
A23: North | B23: =SUMIF(CustomerData[Region],A23,CustomerData[Revenue]) -> 67150
A24: South | B24: =SUMIF(CustomerData[Region],A24,CustomerData[Revenue]) -> 59950
A25: East | B25: =SUMIF(CustomerData[Region],A25,CustomerData[Revenue]) -> 76450
A26: West | B26: =SUMIF(CustomerData[Region],A26,CustomerData[Revenue]) -> 91050
A28: Highest Revenue Region | B28: =INDEX(A23:A26,MATCH(MAX(B23:B26),B23:B26,0)) -> West
A30: Profit by Product Category
A31: Product Category | B31: Profit
A32: Electronics | B32: =SUMIF(CustomerData[Product_Category],A32,CustomerData[Profit]) -> 30600
A33: Home & Kitchen | B33: =SUMIF(CustomerData[Product_Category],A33,CustomerData[Profit]) -> 22800
A34: Personal Care | B34: =SUMIF(CustomerData[Product_Category],A34,CustomerData[Profit]) -> 13050
A35: Accessories | B35: =SUMIF(CustomerData[Product_Category],A35,CustomerData[Profit]) -> 15100
A37: Highest Profit Category | B37: =INDEX(A32:A35,MATCH(MAX(B32:B35),B32:B35,0)) -> Electronics
A39: Profit by Region
A40: Region | B40: Profit
A41: North | B41: =SUMIF(CustomerData[Region],A41,CustomerData[Profit]) -> 19800
A42: South | B42: =SUMIF(CustomerData[Region],A42,CustomerData[Profit]) -> 17700
A43: East | B43: =SUMIF(CustomerData[Region],A43,CustomerData[Profit]) -> 21450
A44: West | B44: =SUMIF(CustomerData[Region],A44,CustomerData[Profit]) -> 25700
A46: Highest Profit Region | B46: =INDEX(A41:A44,MATCH(MAX(B41:B44),B41:B44,0)) -> West
A48: Revenue by Customer Type
A49: Customer Type | B49: Revenue
A50: New | B50: =SUMIF('Raw Data'!D2:D51,"*New*",'Raw Data'!I2:I51) -> 164300
...

Sheet Dashboard
A1: Customer & Business Performance Dashboard
A3: Total Customers | B3: Total Orders | C3: Total Revenue | D3: Total Profit | E3: Profit Margin
A4: =Analysis!B3 -> 50 | B4: =Analysis!B4 -> 50 | C4: =Analysis!B5 -> 294600 | D4: =Analysis!B6 -> 84650 | E4: =Analysis!B8 -> 0.28733876

Sheet Insights
A1: Customer &Business Performance Insights
A3: Key Business Insights
A4: Highest Revenue Product Category | B4: =Analysis!B19 -> Electronics
A5: Highest Profit Product Category | B5: =Analysis!B37 -> Electronics
A6: Highest Revenue Region | B6: =Analysis!B28 -> West
A7: Highest Profit Region | B7: =Analysis!B46 -> West
A8: Higher Revenue Customer Type | B8: =Analysis!B53 -> New
A10: Business Recommendations
A11: Focus on high-performing product categories
A12: Analyze regional performance to identify opportunities
A13: Monitor monthly revenue trends for business planning
A14: Track customer ratings to maintain service quality
A15: Compare customer segments to understand revenue contribution
